<sdf version='1.7'>
  <world name='default'>
    <light name='sun' type='directional'>
      <cast_shadows>1</cast_shadows>
      <pose>0 0 10 0 -0 0</pose>
      <diffuse>0.8 0.8 0.8 1</diffuse>
      <specular>0.2 0.2 0.2 1</specular>
      <attenuation>
        <range>1000</range>
        <constant>0.9</constant>
        <linear>0.01</linear>
        <quadratic>0.001</quadratic>
      </attenuation>
      <direction>-0.5 0.1 -0.9</direction>
      <spot>
        <inner_angle>0</inner_angle>
        <outer_angle>0</outer_angle>
        <falloff>0</falloff>
      </spot>
    </light>
    <model name='ground_plane'>
      <static>1</static>
      <link name='link'>
        <collision name='collision'>
          <geometry>
            <plane>
              <normal>0 0 1</normal>
              <size>100 100</size>
            </plane>
          </geometry>
          <surface>
            <friction>
              <ode>
                <mu>100</mu>
                <mu2>50</mu2>
              </ode>
              <torsional>
                <ode/>
              </torsional>
            </friction>
            <contact>
              <ode/>
            </contact>
            <bounce/>
          </surface>
          <max_contacts>10</max_contacts>
        </collision>
        <visual name='visual'>
          <cast_shadows>0</cast_shadows>
          <geometry>
            <plane>
              <normal>0 0 1</normal>
              <size>100 100</size>
            </plane>
          </geometry>
          <material>
            <script>
              <uri>file://media/materials/scripts/gazebo.material</uri>
              <name>Gazebo/Grey</name>
            </script>
          </material>
        </visual>
        <self_collide>0</self_collide>
        <enable_wind>0</enable_wind>
        <kinematic>0</kinematic>
      </link>
    </model>
    <gravity>0 0 -9.8</gravity>
    <magnetic_field>6e-06 2.3e-05 -4.2e-05</magnetic_field>
    <atmosphere type='adiabatic'/>
    <physics type='ode'>
      <max_step_size>0.001</max_step_size>
      <real_time_factor>1</real_time_factor>
      <real_time_update_rate>1000</real_time_update_rate>
    </physics>
    <scene>
      <ambient>0.4 0.4 0.4 1</ambient>
      <background>0.7 0.7 0.7 1</background>
      <shadows>1</shadows>
    </scene>
    <audio>
      <device>default</device>
    </audio>
    <wind/>
    <spherical_coordinates>
      <surface_model>EARTH_WGS84</surface_model>
      <latitude_deg>0</latitude_deg>
      <longitude_deg>0</longitude_deg>
      <elevation>0</elevation>
      <heading_deg>0</heading_deg>
    </spherical_coordinates>
    <model name='my_bot'>
      <link name='base_link'>
        <inertial>
          <pose>0.016641 9.1e-05 -0.089499 0 -0 0</pose>
          <mass>8.61221</mass>
          <inertia>
            <ixx>0.619106</ixx>
            <ixy>-1.34315e-06</ixy>
            <ixz>0.00686548</ixz>
            <iyy>1.29237</iyy>
            <iyz>3.59477e-05</iyz>
            <izz>1.10239</izz>
          </inertia>
        </inertial>
        <collision name='base_link_collision'>
          <pose>0 0 0 0 -0 0</pose>
          <geometry>
            <mesh>
              <scale>1 1 1</scale>
              <uri>/home/mystique/dev_ws/install/diablo_bot/share/diablo_bot/description/meshes/base_link.STL</uri>
            </mesh>
          </geometry>
          <surface>
            <contact>
              <ode/>
            </contact>
            <friction>
              <ode/>
              <torsional>
                <ode/>
              </torsional>
            </friction>
            <bounce/>
          </surface>
          <max_contacts>10</max_contacts>
        </collision>
        <collision name='base_link_fixed_joint_lump__head_pan_Link_collision_1'>
          <pose>-0.012051 0 0.3059 0 -0 1.5708</pose>
          <geometry>
            <mesh>
              <scale>1 1 1</scale>
              <uri>/home/mystique/dev_ws/install/diablo_bot/share/diablo_bot/description/meshes/head_pan_Link.STL</uri>
            </mesh>
          </geometry>
          <max_contacts>10</max_contacts>
          <surface>
            <contact>
              <ode/>
            </contact>
            <bounce/>
            <friction>
              <torsional>
                <ode/>
              </torsional>
              <ode/>
            </friction>
          </surface>
        </collision>
        <collision name='base_link_fixed_joint_lump__head_tilt_Link_collision_2'>
          <pose>0.000949 0.024 0.3189 1.5708 -0 0</pose>
          <geometry>
            <mesh>
              <scale>1 1 1</scale>
              <uri>/home/mystique/dev_ws/install/diablo_bot/share/diablo_bot/description/meshes/head_tilt_Link.STL</uri>
            </mesh>
          </geometry>
          <max_contacts>10</max_contacts>
          <surface>
            <contact>
              <ode/>
            </contact>
            <bounce/>
            <friction>
              <torsional>
                <ode/>
              </torsional>
              <ode/>
            </friction>
          </surface>
        </collision>
        <collision name='base_link_fixed_joint_lump__lower_base_link_collision_3'>
          <pose>0 0 -0.5 0 -0 0</pose>
          <geometry>
            <mesh>
              <scale>0.001 0.001 0.001</scale>
              <uri>/home/mystique/dev_ws/install/diablo_bot/share/diablo_bot/description/meshes/lower_base_link.stl</uri>
            </mesh>
          </geometry>
          <max_contacts>10</max_contacts>
          <surface>
            <contact>
              <ode/>
            </contact>
            <bounce/>
            <friction>
              <torsional>
                <ode/>
              </torsional>
              <ode/>
            </friction>
          </surface>
        </collision>
        <visual name='base_link_visual'>
          <pose>0 0 0 0 -0 0</pose>
          <geometry>
            <mesh>
              <scale>1 1 1</scale>
              <uri>/home/mystique/dev_ws/install/diablo_bot/share/diablo_bot/description/meshes/base_link.STL</uri>
            </mesh>
          </geometry>
          <material>
            <script>
              <name>Gazebo/Silver</name>
              <uri>file://media/materials/scripts/gazebo.material</uri>
            </script>
          </material>
        </visual>
        <visual name='base_link_fixed_joint_lump__head_pan_Link_visual_1'>
          <pose>-0.012051 0 0.3059 0 -0 1.5708</pose>
          <geometry>
            <mesh>
              <scale>1 1 1</scale>
              <uri>/home/mystique/dev_ws/install/diablo_bot/share/diablo_bot/description/meshes/head_pan_Link.STL</uri>
            </mesh>
          </geometry>
        </visual>
        <visual name='base_link_fixed_joint_lump__head_tilt_Link_visual_2'>
          <pose>0.000949 0.024 0.3189 1.5708 -0 0</pose>
          <geometry>
            <mesh>
              <scale>1 1 1</scale>
              <uri>/home/mystique/dev_ws/install/diablo_bot/share/diablo_bot/description/meshes/head_tilt_Link.STL</uri>
            </mesh>
          </geometry>
        </visual>
        <visual name='base_link_fixed_joint_lump__lower_base_link_visual_3'>
          <pose>0 0 -0.5 0 -0 0</pose>
          <geometry>
            <mesh>
              <scale>0.001 0.001 0.001</scale>
              <uri>/home/mystique/dev_ws/install/diablo_bot/share/diablo_bot/description/meshes/lower_base_link.stl</uri>
            </mesh>
          </geometry>
        </visual>
        <self_collide>0</self_collide>
        <enable_wind>0</enable_wind>
        <kinematic>0</kinematic>
      </link>
      <joint name='l_sho_pitch' type='revolute'>
        <pose relative_to='base_link'>-0.012051 0.09965 0.26225 1.5708 -0 3.14159</pose>
        <parent>base_link</parent>
        <child>l_sho_pitch_Link</child>
        <axis>
          <xyz>0 0 -1</xyz>
          <limit>
            <lower>0</lower>
            <upper>0</upper>
            <effort>4.1</effort>
            <velocity>4.71</velocity>
          </limit>
          <dynamics>
            <spring_reference>0</spring_reference>
            <spring_stiffness>0</spring_stiffness>
          </dynamics>
        </axis>
      </joint>
      <link name='l_sho_pitch_Link'>
        <pose relative_to='l_sho_pitch'>0 0 0 0 -0 0</pose>
        <inertial>
          <pose>-0.000541 -0 0.024565 0 -0 0</pose>
          <mass>0.0454925</mass>
          <inertia>
            <ixx>1.06543e-05</ixx>
            <ixy>4.23803e-20</ixy>
            <ixz>-1.18102e-09</ixz>
            <iyy>1.2432e-05</iyy>
            <iyz>2.70982e-20</iyz>
            <izz>7.52175e-06</izz>
          </inertia>
        </inertial>
        <collision name='l_sho_pitch_Link_collision'>
          <pose>0 0 0 0 -0 0</pose>
          <geometry>
            <mesh>
              <scale>1 1 1</scale>
              <uri>/home/mystique/dev_ws/install/diablo_bot/share/diablo_bot/description/meshes/l_sho_pitch_Link.STL</uri>
            </mesh>
          </geometry>
          <max_contacts>10</max_contacts>
          <surface>
            <contact>
              <ode/>
            </contact>
            <bounce/>
            <friction>
              <torsional>
                <ode/>
              </torsional>
              <ode/>
            </friction>
          </surface>
        </collision>
        <visual name='l_sho_pitch_Link_visual'>
          <pose>0 0 0 0 -0 0</pose>
          <geometry>
            <mesh>
              <scale>1 1 1</scale>
              <uri>/home/mystique/dev_ws/install/diablo_bot/share/diablo_bot/description/meshes/l_sho_pitch_Link.STL</uri>
            </mesh>
          </geometry>
        </visual>
        <self_collide>0</self_collide>
        <enable_wind>0</enable_wind>
        <kinematic>0</kinematic>
      </link>
      <joint name='l_sho_roll' type='revolute'>
        <pose relative_to='l_sho_pitch_Link'>-0.0234 0 0.03735 3.14159 1.57079 3.14159</pose>
        <parent>l_sho_pitch_Link</parent>
        <child>l_sho_roll_Link</child>
        <axis>
          <xyz>0 0 1</xyz>
          <limit>
            <lower>0.9</lower>
            <upper>1.6</upper>
            <effort>4.1</effort>
            <velocity>4.71</velocity>
          </limit>
          <dynamics>
            <spring_reference>0</spring_reference>
            <spring_stiffness>0</spring_stiffness>
          </dynamics>
        </axis>
      </joint>
      <link name='l_sho_roll_Link'>
        <pose relative_to='l_sho_roll'>0 0 0 0 -0 0</pose>
        <inertial>
          <pose>-0.114571 0.000361 0.0234 0 -0 0</pose>
          <mass>0.0683067</mass>
          <inertia>
            <ixx>1.14189e-05</ixx>
            <ixy>-1.22523e-09</ixy>
            <ixz>7.04706e-13</ixz>
            <iyy>2.35951e-05</iyy>
            <iyz>1.56834e-13</iyz>
            <izz>2.34186e-05</izz>
          </inertia>
        </inertial>
        <collision name='l_sho_roll_Link_collision'>
          <pose>0 0 0 0 -0 0</pose>
          <geometry>
            <mesh>
              <scale>1 1 1</scale>
              <uri>/home/mystique/dev_ws/install/diablo_bot/share/diablo_bot/description/meshes/l_sho_roll_Link.STL</uri>
            </mesh>
          </geometry>
          <max_contacts>10</max_contacts>
          <surface>
            <contact>
              <ode/>
            </contact>
            <bounce/>
            <friction>
              <torsional>
                <ode/>
              </torsional>
              <ode/>
            </friction>
          </surface>
        </collision>
        <visual name='l_sho_roll_Link_visual'>
          <pose>0 0 0 0 -0 0</pose>
          <geometry>
            <mesh>
              <scale>1 1 1</scale>
              <uri>/home/mystique/dev_ws/install/diablo_bot/share/diablo_bot/description/meshes/l_sho_roll_Link.STL</uri>
            </mesh>
          </geometry>
        </visual>
        <self_collide>0</self_collide>
        <enable_wind>0</enable_wind>
        <kinematic>0</kinematic>
      </link>
      <joint name='l_el' type='revolute'>
        <pose relative_to='l_sho_roll_Link'>-0.14975 0.0234 0.0234 1.5708 -0 3.14159</pose>
        <parent>l_sho_roll_Link</parent>
        <child>l_el_Link</child>
        <axis>
          <xyz>0 0 -1</xyz>
          <limit>
            <lower>0</lower>
            <upper>1.57</upper>
            <effort>4.1</effort>
            <velocity>4.71</velocity>
          </limit>
          <dynamics>
            <spring_reference>0</spring_reference>
            <spring_stiffness>0</spring_stiffness>
          </dynamics>
        </axis>
      </joint>
      <link name='l_el_Link'>
        <pose relative_to='l_el'>0 0 0 0 -0 0</pose>
        <inertial>
          <pose>0.068089 0.001693 -0.026861 0 -0 0</pose>
          <mass>0.305317</mass>
          <inertia>
            <ixx>0.0975728</ixx>
            <ixy>-0.000378491</ixy>
            <ixz>-0.000297669</ixz>
            <iyy>1.0178</iyy>
            <iyz>0.00159419</iyz>
            <izz>0.931972</izz>
          </inertia>
        </inertial>
        <collision name='l_el_Link_collision'>
          <pose>0 0 0 0 -0 0</pose>
          <geometry>
            <mesh>
              <scale>1 1 1</scale>
              <uri>/home/mystique/dev_ws/install/diablo_bot/share/diablo_bot/description/meshes/l_el_Link.STL</uri>
            </mesh>
          </geometry>
          <max_contacts>10</max_contacts>
          <surface>
            <contact>
              <ode/>
            </contact>
            <bounce/>
            <friction>
              <torsional>
                <ode/>
              </torsional>
              <ode/>
            </friction>
          </surface>
        </collision>
        <collision name='l_el_Link_fixed_joint_lump__l_wrist_Link_collision_1'>
          <pose>0.091 0.000113 -0.023557 1.5708 -0 1.53589</pose>
          <geometry>
            <mesh>
              <scale>1 1 1</scale>
              <uri>/home/mystique/dev_ws/install/diablo_bot/share/diablo_bot/description/meshes/l_wrist_Link.STL</uri>
            </mesh>
          </geometry>
          <max_contacts>10</max_contacts>
          <surface>
            <contact>
              <ode/>
            </contact>
            <bounce/>
            <friction>
              <torsional>
                <ode/>
              </torsional>
              <ode/>
            </friction>
          </surface>
        </collision>
        <collision name='l_el_Link_fixed_joint_lump__l_index_base_Link_collision_2'>
          <pose>0.185941 0.014719 -0.008655 -4e-06 0 -1e-05</pose>
          <geometry>
            <mesh>
              <scale>1 1 1</scale>
              <uri>/home/mystique/dev_ws/install/diablo_bot/share/diablo_bot/description/meshes/l_index_base_Link.STL</uri>
            </mesh>
          </geometry>
          <max_contacts>10</max_contacts>
          <surface>
            <contact>
              <ode/>
            </contact>
            <bounce/>
            <friction>
              <torsional>
                <ode/>
              </torsional>
              <ode/>
            </friction>
          </surface>
        </collision>
        <collision name='l_el_Link_fixed_joint_lump__l_index_middle_Link_collision_3'>
          <pose>0.200476 0.021508 -0.007947 -4e-06 0 -1e-05</pose>
          <geometry>
            <mesh>
              <scale>1 1 1</scale>
              <uri>/home/mystique/dev_ws/install/diablo_bot/share/diablo_bot/description/meshes/l_index_middle_Link.STL</uri>
            </mesh>
          </geometry>
          <max_contacts>10</max_contacts>
          <surface>
            <contact>
              <ode/>
            </contact>
            <bounce/>
            <friction>
              <torsional>
                <ode/>
              </torsional>
              <ode/>
            </friction>
          </surface>
        </collision>
        <collision name='l_el_Link_fixed_joint_lump__l_index_tip_Link_collision_4'>
          <pose>0.21542 0.02694 -0.006152 -4e-06 0 -1e-05</pose>
          <geometry>
            <mesh>
              <scale>1 1 1</scale>
              <uri>/home/mystique/dev_ws/install/diablo_bot/share/diablo_bot/description/meshes/l_index_tip_Link.STL</uri>
            </mesh>
          </geometry>
          <max_contacts>10</max_contacts>
          <surface>
            <contact>
              <ode/>
            </contact>
            <bounce/>
            <friction>
              <torsional>
                <ode/>
              </torsional>
              <ode/>
            </friction>
          </surface>
        </collision>
        <collision name='l_el_Link_fixed_joint_lump__l_mid_base_Link_collision_5'>
          <pose>0.184747 0.013656 -0.0491 -4e-06 0 -1e-05</pose>
          <geometry>
            <mesh>
              <scale>1 1 1</scale>
              <uri>/home/mystique/dev_ws/install/diablo_bot/share/diablo_bot/description/meshes/l_mid_base_Link.STL</uri>
            </mesh>
          </geometry>
          <max_contacts>10</max_contacts>
          <surface>
            <contact>
              <ode/>
            </contact>
            <bounce/>
            <friction>
              <torsional>
                <ode/>
              </torsional>
              <ode/>
            </friction>
          </surface>
        </collision>
        <collision name='l_el_Link_fixed_joint_lump__l_mid_middle_Link_collision_6'>
          <pose>0.198972 0.020221 -0.052623 -4e-06 0 -1e-05</pose>
          <geometry>
            <mesh>
              <scale>1 1 1</scale>
              <uri>/home/mystique/dev_ws/install/diablo_bot/share/diablo_bot/description/meshes/l_mid_middle_Link.STL</uri>
            </mesh>
          </geometry>
          <max_contacts>10</max_contacts>
          <surface>
            <contact>
              <ode/>
            </contact>
            <bounce/>
            <friction>
              <torsional>
                <ode/>
              </torsional>
              <ode/>
            </friction>
          </surface>
        </collision>
        <collision name='l_el_Link_fixed_joint_lump__l_mid_tip_Link_collision_7'>
          <pose>0.213888 0.025603 -0.054755 -4e-06 0 -1e-05</pose>
          <geometry>
            <mesh>
              <scale>1 1 1</scale>
              <uri>/home/mystique/dev_ws/install/diablo_bot/share/diablo_bot/description/meshes/l_mid_tip_Link.STL</uri>
            </mesh>
          </geometry>
          <max_contacts>10</max_contacts>
          <surface>
            <contact>
              <ode/>
            </contact>
            <bounce/>
            <friction>
              <torsional>
                <ode/>
              </torsional>
              <ode/>
            </friction>
          </surface>
        </collision>
        <collision name='l_el_Link_fixed_joint_lump__l_thumb_base_Link_collision_8'>
          <pose>0.169953 -0.026716 -0.018084 -4e-06 0 -1e-05</pose>
          <geometry>
            <mesh>
              <scale>1 1 1</scale>
              <uri>/home/mystique/dev_ws/install/diablo_bot/share/diablo_bot/description/meshes/l_thumb_base_Link.STL</uri>
            </mesh>
          </geometry>
          <max_contacts>10</max_contacts>
          <surface>
            <contact>
              <ode/>
            </contact>
            <bounce/>
            <friction>
              <torsional>
                <ode/>
              </torsional>
              <ode/>
            </friction>
          </surface>
        </collision>
        <collision name='l_el_Link_fixed_joint_lump__l_thumb_middle_Link_collision_9'>
          <pose>0.175425 -0.041849 -0.029822 -4e-06 0 -1e-05</pose>
          <geometry>
            <mesh>
              <scale>1 1 1</scale>
              <uri>/home/mystique/dev_ws/install/diablo_bot/share/diablo_bot/description/meshes/l_thumb_middle_Link.STL</uri>
            </mesh>
          </geometry>
          <max_contacts>10</max_contacts>
          <surface>
            <contact>
              <ode/>
            </contact>
            <bounce/>
            <friction>
              <torsional>
                <ode/>
              </torsional>
              <ode/>
            </friction>
          </surface>
        </collision>
        <collision name='l_el_Link_fixed_joint_lump__l_thumb_tip_Link_collision_10'>
          <pose>0.180897 -0.056884 -0.029697 -4e-06 0 -1e-05</pose>
          <geometry>
            <mesh>
              <scale>1 1 1</scale>
              <uri>/home/mystique/dev_ws/install/diablo_bot/share/diablo_bot/description/meshes/l_thumb_tip_Link.STL</uri>
            </mesh>
          </geometry>
          <max_contacts>10</max_contacts>
          <surface>
            <contact>
              <ode/>
            </contact>
            <bounce/>
            <friction>
              <torsional>
                <ode/>
              </torsional>
              <ode/>
            </friction>
          </surface>
        </collision>
        <visual name='l_el_Link_visual'>
          <pose>0 0 0 0 -0 0</pose>
          <geometry>
            <mesh>
              <scale>1 1 1</scale>
              <uri>/home/mystique/dev_ws/install/diablo_bot/share/diablo_bot/description/meshes/l_el_Link.STL</uri>
            </mesh>
          </geometry>
        </visual>
        <visual name='l_el_Link_fixed_joint_lump__l_wrist_Link_visual_1'>
          <pose>0.091 0.000113 -0.023557 1.5708 -0 1.53589</pose>
          <geometry>
            <mesh>
              <scale>1 1 1</scale>
              <uri>/home/mystique/dev_ws/install/diablo_bot/share/diablo_bot/description/meshes/l_wrist_Link.STL</uri>
            </mesh>
          </geometry>
        </visual>
        <visual name='l_el_Link_fixed_joint_lump__l_index_base_Link_visual_2'>
          <pose>0.185941 0.014719 -0.008655 -4e-06 0 -1e-05</pose>
          <geometry>
            <mesh>
              <scale>1 1 1</scale>
              <uri>/home/mystique/dev_ws/install/diablo_bot/share/diablo_bot/description/meshes/l_index_base_Link.STL</uri>
            </mesh>
          </geometry>
        </visual>
        <visual name='l_el_Link_fixed_joint_lump__l_index_middle_Link_visual_3'>
          <pose>0.200476 0.021508 -0.007947 -4e-06 0 -1e-05</pose>
          <geometry>
            <mesh>
              <scale>1 1 1</scale>
              <uri>/home/mystique/dev_ws/install/diablo_bot/share/diablo_bot/description/meshes/l_index_middle_Link.STL</uri>
            </mesh>
          </geometry>
        </visual>
        <visual name='l_el_Link_fixed_joint_lump__l_index_tip_Link_visual_4'>
          <pose>0.21542 0.02694 -0.006152 -4e-06 0 -1e-05</pose>
          <geometry>
            <mesh>
              <scale>1 1 1</scale>
              <uri>/home/mystique/dev_ws/install/diablo_bot/share/diablo_bot/description/meshes/l_index_tip_Link.STL</uri>
            </mesh>
          </geometry>
        </visual>
        <visual name='l_el_Link_fixed_joint_lump__l_mid_base_Link_visual_5'>
          <pose>0.184747 0.013656 -0.0491 -4e-06 0 -1e-05</pose>
          <geometry>
            <mesh>
              <scale>1 1 1</scale>
              <uri>/home/mystique/dev_ws/install/diablo_bot/share/diablo_bot/description/meshes/l_mid_base_Link.STL</uri>
            </mesh>
          </geometry>
        </visual>
        <visual name='l_el_Link_fixed_joint_lump__l_mid_middle_Link_visual_6'>
          <pose>0.198972 0.020221 -0.052623 -4e-06 0 -1e-05</pose>
          <geometry>
            <mesh>
              <scale>1 1 1</scale>
              <uri>/home/mystique/dev_ws/install/diablo_bot/share/diablo_bot/description/meshes/l_mid_middle_Link.STL</uri>
            </mesh>
          </geometry>
        </visual>
        <visual name='l_el_Link_fixed_joint_lump__l_mid_tip_Link_visual_7'>
          <pose>0.213888 0.025603 -0.054755 -4e-06 0 -1e-05</pose>
          <geometry>
            <mesh>
              <scale>1 1 1</scale>
              <uri>/home/mystique/dev_ws/install/diablo_bot/share/diablo_bot/description/meshes/l_mid_tip_Link.STL</uri>
            </mesh>
          </geometry>
        </visual>
        <visual name='l_el_Link_fixed_joint_lump__l_thumb_base_Link_visual_8'>
          <pose>0.169953 -0.026716 -0.018084 -4e-06 0 -1e-05</pose>
          <geometry>
            <mesh>
              <scale>1 1 1</scale>
              <uri>/home/mystique/dev_ws/install/diablo_bot/share/diablo_bot/description/meshes/l_thumb_base_Link.STL</uri>
            </mesh>
          </geometry>
        </visual>
        <visual name='l_el_Link_fixed_joint_lump__l_thumb_middle_Link_visual_9'>
          <pose>0.175425 -0.041849 -0.029822 -4e-06 0 -1e-05</pose>
          <geometry>
            <mesh>
              <scale>1 1 1</scale>
              <uri>/home/mystique/dev_ws/install/diablo_bot/share/diablo_bot/description/meshes/l_thumb_middle_Link.STL</uri>
            </mesh>
          </geometry>
        </visual>
        <visual name='l_el_Link_fixed_joint_lump__l_thumb_tip_Link_visual_10'>
          <pose>0.180897 -0.056884 -0.029697 -4e-06 0 -1e-05</pose>
          <geometry>
            <mesh>
              <scale>1 1 1</scale>
              <uri>/home/mystique/dev_ws/install/diablo_bot/share/diablo_bot/description/meshes/l_thumb_tip_Link.STL</uri>
            </mesh>
          </geometry>
        </visual>
        <self_collide>0</self_collide>
        <enable_wind>0</enable_wind>
        <kinematic>0</kinematic>
      </link>
      <joint name='l1' type='revolute'>
        <pose relative_to='base_link'>0.00036 0.053553 -0.121 0 -0 0</pose>
        <parent>base_link</parent>
        <child>motor_left_link_1</child>
        <axis>
          <xyz>0 1 0</xyz>
          <limit>
            <effort>9.6</effort>
            <velocity>12.05</velocity>
            <lower>-1e+16</lower>
            <upper>1e+16</upper>
          </limit>
          <dynamics>
            <damping>0</damping>
            <friction>0</friction>
            <spring_reference>0</spring_reference>
            <spring_stiffness>0</spring_stiffness>
          </dynamics>
        </axis>
      </joint>
      <link name='motor_left_link_1'>
        <pose relative_to='l1'>0 0 0 0 -0 0</pose>
        <inertial>
          <pose>0.000158 0.067983 -0.001799 0 -0 0</pose>
          <mass>4.65</mass>
          <inertia>
            <ixx>0.0300227</ixx>
            <ixy>-4.25399e-05</ixy>
            <ixz>0.000229131</ixz>
            <iyy>0.0300775</iyy>
            <iyz>0.000679053</iyz>
            <izz>0.0267843</izz>
          </inertia>
        </inertial>
        <collision name='motor_left_link_1_collision'>
          <pose>-0.00036 -0.053553 -0.379 0 -0 0</pose>
          <geometry>
            <mesh>
              <scale>0.001 0.001 0.001</scale>
              <uri>/home/mystique/dev_ws/install/diablo_bot/share/diablo_bot/description/meshes/motor_left_link_1.stl</uri>
            </mesh>
          </geometry>
          <max_contacts>10</max_contacts>
          <surface>
            <contact>
              <ode/>
            </contact>
            <bounce/>
            <friction>
              <torsional>
                <ode/>
              </torsional>
              <ode/>
            </friction>
          </surface>
        </collision>
        <collision name='motor_left_link_1_fixed_joint_lump__leg_left_link_1_collision_1'>
          <pose>-0.00036 -0.053553 -0.379 0 -0 0</pose>
          <geometry>
            <mesh>
              <scale>0.001 0.001 0.001</scale>
              <uri>/home/mystique/dev_ws/install/diablo_bot/share/diablo_bot/description/meshes/leg_left_link_1.stl</uri>
            </mesh>
          </geometry>
          <max_contacts>10</max_contacts>
          <surface>
            <contact>
              <ode/>
            </contact>
            <bounce/>
            <friction>
              <torsional>
                <ode/>
              </torsional>
              <ode/>
            </friction>
          </surface>
        </collision>
        <visual name='motor_left_link_1_visual'>
          <pose>-0.00036 -0.053553 -0.379 0 -0 0</pose>
          <geometry>
            <mesh>
              <scale>0.001 0.001 0.001</scale>
              <uri>/home/mystique/dev_ws/install/diablo_bot/share/diablo_bot/description/meshes/motor_left_link_1.stl</uri>
            </mesh>
          </geometry>
        </visual>
        <visual name='motor_left_link_1_fixed_joint_lump__leg_left_link_1_visual_1'>
          <pose>-0.00036 -0.053553 -0.379 0 -0 0</pose>
          <geometry>
            <mesh>
              <scale>0.001 0.001 0.001</scale>
              <uri>/home/mystique/dev_ws/install/diablo_bot/share/diablo_bot/description/meshes/leg_left_link_1.stl</uri>
            </mesh>
          </geometry>
        </visual>
        <self_collide>0</self_collide>
        <enable_wind>0</enable_wind>
        <kinematic>0</kinematic>
      </link>
      <joint name='l3' type='revolute'>
        <pose relative_to='motor_left_link_1'>0 0.1341 -0.14 0 -0 0</pose>
        <parent>motor_left_link_1</parent>
        <child>leg2_left_link_1</child>
        <axis>
          <xyz>0 1 0</xyz>
          <limit>
            <effort>9.6</effort>
            <velocity>12.05</velocity>
            <lower>-1e+16</lower>
            <upper>1e+16</upper>
          </limit>
          <dynamics>
            <damping>0</damping>
            <friction>0</friction>
            <spring_reference>0</spring_reference>
            <spring_stiffness>0</spring_stiffness>
          </dynamics>
        </axis>
      </joint>
      <link name='leg2_left_link_1'>
        <pose relative_to='l3'>0 0 0 0 -0 0</pose>
        <inertial>
          <pose>2e-06 0.012348 -0.092364 0 -0 0</pose>
          <mass>0.05</mass>
          <inertia>
            <ixx>0.003787</ixx>
            <ixy>0</ixy>
            <ixz>0</ixz>
            <iyy>0.003963</iyy>
            <iyz>5.8e-05</iyz>
            <izz>0.000327</izz>
          </inertia>
        </inertial>
        <collision name='leg2_left_link_1_collision'>
          <pose>-0.00036 -0.187653 -0.239 0 -0 0</pose>
          <geometry>
            <mesh>
              <scale>0.001 0.001 0.001</scale>
              <uri>/home/mystique/dev_ws/install/diablo_bot/share/diablo_bot/description/meshes/leg2_left_link_1.stl</uri>
            </mesh>
          </geometry>
          <max_contacts>10</max_contacts>
          <surface>
            <contact>
              <ode/>
            </contact>
            <bounce/>
            <friction>
              <torsional>
                <ode/>
              </torsional>
              <ode/>
            </friction>
          </surface>
        </collision>
        <visual name='leg2_left_link_1_visual'>
          <pose>-0.00036 -0.187653 -0.239 0 -0 0</pose>
          <geometry>
            <mesh>
              <scale>0.001 0.001 0.001</scale>
              <uri>/home/mystique/dev_ws/install/diablo_bot/share/diablo_bot/description/meshes/leg2_left_link_1.stl</uri>
            </mesh>
          </geometry>
        </visual>
        <self_collide>0</self_collide>
        <enable_wind>0</enable_wind>
        <kinematic>0</kinematic>
      </link>
      <joint name='l4' type='revolute'>
        <pose relative_to='leg2_left_link_1'>0 0.0277 -0.14 0 -0 0</pose>
        <parent>leg2_left_link_1</parent>
        <child>wheel_left_link_1</child>
        <axis>
          <xyz>0 1 0</xyz>
          <limit>
            <effort>9.6</effort>
            <velocity>12.05</velocity>
            <lower>-1e+16</lower>
            <upper>1e+16</upper>
          </limit>
          <dynamics>
            <damping>0</damping>
            <friction>0</friction>
            <spring_reference>0</spring_reference>
            <spring_stiffness>0</spring_stiffness>
          </dynamics>
        </axis>
      </joint>
      <link name='wheel_left_link_1'>
        <pose relative_to='l4'>0 0 0 0 -0 0</pose>
        <inertial>
          <pose>0 0.026 -0 0 -0 0</pose>
          <mass>2.5</mass>
          <inertia>
            <ixx>0.025678</ixx>
            <ixy>0</ixy>
            <ixz>0</ixz>
            <iyy>0.046537</iyy>
            <iyz>0</iyz>
            <izz>0.025678</izz>
          </inertia>
        </inertial>
        <collision name='wheel_left_link_1_collision'>
          <pose>-0.00036 -0.215353 -0.099 0 -0 0</pose>
          <geometry>
            <mesh>
              <scale>0.001 0.001 0.001</scale>
              <uri>/home/mystique/dev_ws/install/diablo_bot/share/diablo_bot/description/meshes/wheel_right_link_1.stl</uri>
            </mesh>
          </geometry>
          <max_contacts>10</max_contacts>
          <surface>
            <contact>
              <ode/>
            </contact>
            <bounce/>
            <friction>
              <torsional>
                <ode/>
              </torsional>
              <ode/>
            </friction>
          </surface>
        </collision>
        <visual name='wheel_left_link_1_visual'>
          <pose>-0.00036 -0.215353 -0.099 0 -0 0</pose>
          <geometry>
            <mesh>
              <scale>0.001 0.001 0.001</scale>
              <uri>/home/mystique/dev_ws/install/diablo_bot/share/diablo_bot/description/meshes/wheel_right_link_1.stl</uri>
            </mesh>
          </geometry>
        </visual>
        <self_collide>0</self_collide>
        <enable_wind>0</enable_wind>
        <kinematic>0</kinematic>
      </link>
      <joint name='r1' type='revolute'>
        <pose relative_to='base_link'>0.00036 -0.053347 -0.121 0 -0 0</pose>
        <parent>base_link</parent>
        <child>motor_right_link_1</child>
        <axis>
          <xyz>0 -1 0</xyz>
          <limit>
            <effort>9.6</effort>
            <velocity>12.05</velocity>
            <lower>-1e+16</lower>
            <upper>1e+16</upper>
          </limit>
          <dynamics>
            <damping>0</damping>
            <friction>0</friction>
            <spring_reference>0</spring_reference>
            <spring_stiffness>0</spring_stiffness>
          </dynamics>
        </axis>
      </joint>
      <link name='motor_right_link_1'>
        <pose relative_to='r1'>0 0 0 0 -0 0</pose>
        <inertial>
          <pose>0.000158 -0.067982 -0.001799 0 -0 0</pose>
          <mass>4.65</mass>
          <inertia>
            <ixx>0.0300227</ixx>
            <ixy>4.25401e-05</ixy>
            <ixz>0.000229131</ixz>
            <iyy>0.0300775</iyy>
            <iyz>-0.000679053</iyz>
            <izz>0.0267843</izz>
          </inertia>
        </inertial>
        <collision name='motor_right_link_1_collision'>
          <pose>-0.00036 0.053347 -0.379 0 -0 0</pose>
          <geometry>
            <mesh>
              <scale>0.001 0.001 0.001</scale>
              <uri>/home/mystique/dev_ws/install/diablo_bot/share/diablo_bot/description/meshes/motor_right_link_1.stl</uri>
            </mesh>
          </geometry>
          <max_contacts>10</max_contacts>
          <surface>
            <contact>
              <ode/>
            </contact>
            <bounce/>
            <friction>
              <torsional>
                <ode/>
              </torsional>
              <ode/>
            </friction>
          </surface>
        </collision>
        <collision name='motor_right_link_1_fixed_joint_lump__leg_right_link_1_collision_1'>
          <pose>-0.00036 0.053347 -0.379 0 -0 0</pose>
          <geometry>
            <mesh>
              <scale>0.001 0.001 0.001</scale>
              <uri>/home/mystique/dev_ws/install/diablo_bot/share/diablo_bot/description/meshes/leg_right_link_1.stl</uri>
            </mesh>
          </geometry>
          <max_contacts>10</max_contacts>
          <surface>
            <contact>
              <ode/>
            </contact>
            <bounce/>
            <friction>
              <torsional>
                <ode/>
              </torsional>
              <ode/>
            </friction>
          </surface>
        </collision>
        <visual name='motor_right_link_1_visual'>
          <pose>-0.00036 0.053347 -0.379 0 -0 0</pose>
          <geometry>
            <mesh>
              <scale>0.001 0.001 0.001</scale>
              <uri>/home/mystique/dev_ws/install/diablo_bot/share/diablo_bot/description/meshes/motor_right_link_1.stl</uri>
            </mesh>
          </geometry>
        </visual>
        <visual name='motor_right_link_1_fixed_joint_lump__leg_right_link_1_visual_1'>
          <pose>-0.00036 0.053347 -0.379 0 -0 0</pose>
          <geometry>
            <mesh>
              <scale>0.001 0.001 0.001</scale>
              <uri>/home/mystique/dev_ws/install/diablo_bot/share/diablo_bot/description/meshes/leg_right_link_1.stl</uri>
            </mesh>
          </geometry>
        </visual>
        <self_collide>0</self_collide>
        <enable_wind>0</enable_wind>
        <kinematic>0</kinematic>
      </link>
      <joint name='r3' type='revolute'>
        <pose relative_to='motor_right_link_1'>0 -0.1341 -0.14 0 -0 0</pose>
        <parent>motor_right_link_1</parent>
        <child>leg2_right_link_1</child>
        <axis>
          <xyz>0 -1 0</xyz>
          <limit>
            <effort>9.6</effort>
            <velocity>12.05</velocity>
            <lower>-1e+16</lower>
            <upper>1e+16</upper>
          </limit>
          <dynamics>
            <damping>0</damping>
            <friction>0</friction>
            <spring_reference>0</spring_reference>
            <spring_stiffness>0</spring_stiffness>
          </dynamics>
        </axis>
      </joint>
      <link name='leg2_right_link_1'>
        <pose relative_to='r3'>0 0 0 0 -0 0</pose>
        <inertial>
          <pose>2e-06 -0.012347 -0.092364 0 -0 0</pose>
          <mass>0.05</mass>
          <inertia>
            <ixx>0.003787</ixx>
            <ixy>0</ixy>
            <ixz>0</ixz>
            <iyy>0.003963</iyy>
            <iyz>-5.8e-05</iyz>
            <izz>0.000327</izz>
          </inertia>
        </inertial>
        <collision name='leg2_right_link_1_collision'>
          <pose>-0.00036 0.187447 -0.239 0 -0 0</pose>
          <geometry>
            <mesh>
              <scale>0.001 0.001 0.001</scale>
              <uri>/home/mystique/dev_ws/install/diablo_bot/share/diablo_bot/description/meshes/leg2_right_link_1.stl</uri>
            </mesh>
          </geometry>
          <max_contacts>10</max_contacts>
          <surface>
            <contact>
              <ode/>
            </contact>
            <bounce/>
            <friction>
              <torsional>
                <ode/>
              </torsional>
              <ode/>
            </friction>
          </surface>
        </collision>
        <visual name='leg2_right_link_1_visual'>
          <pose>-0.00036 0.187447 -0.239 0 -0 0</pose>
          <geometry>
            <mesh>
              <scale>0.001 0.001 0.001</scale>
              <uri>/home/mystique/dev_ws/install/diablo_bot/share/diablo_bot/description/meshes/leg2_right_link_1.stl</uri>
            </mesh>
          </geometry>
        </visual>
        <self_collide>0</self_collide>
        <enable_wind>0</enable_wind>
        <kinematic>0</kinematic>
      </link>
      <joint name='r4' type='revolute'>
        <pose relative_to='leg2_right_link_1'>0 -0.0277 -0.14 0 -0 0</pose>
        <parent>leg2_right_link_1</parent>
        <child>wheel_right_link_1</child>
        <axis>
          <xyz>0 -1 0</xyz>
          <limit>
            <effort>9.6</effort>
            <velocity>12.05</velocity>
            <lower>-1e+16</lower>
            <upper>1e+16</upper>
          </limit>
          <dynamics>
            <damping>0</damping>
            <friction>0</friction>
            <spring_reference>0</spring_reference>
            <spring_stiffness>0</spring_stiffness>
          </dynamics>
        </axis>
      </joint>
      <link name='wheel_right_link_1'>
        <pose relative_to='r4'>0 0 0 0 -0 0</pose>
        <inertial>
          <pose>0 -0.026 -0 0 -0 0</pose>
          <mass>2.5</mass>
          <inertia>
            <ixx>0.025678</ixx>
            <ixy>0</ixy>
            <ixz>0</ixz>
            <iyy>0.046537</iyy>
            <iyz>0</iyz>
            <izz>0.025678</izz>
          </inertia>
        </inertial>
        <collision name='wheel_right_link_1_collision'>
          <pose>-0.00036 0.215147 -0.099 0 -0 0</pose>
          <geometry>
            <mesh>
              <scale>0.001 0.001 0.001</scale>
              <uri>/home/mystique/dev_ws/install/diablo_bot/share/diablo_bot/description/meshes/wheel_left_link_1.stl</uri>
            </mesh>
          </geometry>
          <max_contacts>10</max_contacts>
          <surface>
            <contact>
              <ode/>
            </contact>
            <bounce/>
            <friction>
              <torsional>
                <ode/>
              </torsional>
              <ode/>
            </friction>
          </surface>
        </collision>
        <visual name='wheel_right_link_1_visual'>
          <pose>-0.00036 0.215147 -0.099 0 -0 0</pose>
          <geometry>
            <mesh>
              <scale>0.001 0.001 0.001</scale>
              <uri>/home/mystique/dev_ws/install/diablo_bot/share/diablo_bot/description/meshes/wheel_left_link_1.stl</uri>
            </mesh>
          </geometry>
        </visual>
        <self_collide>0</self_collide>
        <enable_wind>0</enable_wind>
        <kinematic>0</kinematic>
      </link>
      <joint name='r_sho_pitch' type='revolute'>
        <pose relative_to='base_link'>-0.012051 -0.09965 0.26225 1.5708 -0 0</pose>
        <parent>base_link</parent>
        <child>r_sho_pitch_Link</child>
        <axis>
          <xyz>0 0 -1</xyz>
          <limit>
            <lower>-1.9635</lower>
            <upper>1.9635</upper>
            <effort>4.1</effort>
            <velocity>4.71</velocity>
          </limit>
          <dynamics>
            <spring_reference>0</spring_reference>
            <spring_stiffness>0</spring_stiffness>
          </dynamics>
        </axis>
      </joint>
      <link name='r_sho_pitch_Link'>
        <pose relative_to='r_sho_pitch'>0 0 0 0 -0 0</pose>
        <inertial>
          <pose>0.000541 -0 0.024565 0 -0 0</pose>
          <mass>0.0454925</mass>
          <inertia>
            <ixx>1.06543e-05</ixx>
            <ixy>3.1036e-20</ixy>
            <ixz>1.18102e-09</ixz>
            <iyy>1.2432e-05</iyy>
            <iyz>-3.20399e-20</iyz>
            <izz>7.52175e-06</izz>
          </inertia>
        </inertial>
        <collision name='r_sho_pitch_Link_collision'>
          <pose>0 0 0 0 -0 0</pose>
          <geometry>
            <mesh>
              <scale>1 1 1</scale>
              <uri>/home/mystique/dev_ws/install/diablo_bot/share/diablo_bot/description/meshes/r_sho_pitch_Link.STL</uri>
            </mesh>
          </geometry>
          <max_contacts>10</max_contacts>
          <surface>
            <contact>
              <ode/>
            </contact>
            <bounce/>
            <friction>
              <torsional>
                <ode/>
              </torsional>
              <ode/>
            </friction>
          </surface>
        </collision>
        <visual name='r_sho_pitch_Link_visual'>
          <pose>0 0 0 0 -0 0</pose>
          <geometry>
            <mesh>
              <scale>1 1 1</scale>
              <uri>/home/mystique/dev_ws/install/diablo_bot/share/diablo_bot/description/meshes/r_sho_pitch_Link.STL</uri>
            </mesh>
          </geometry>
        </visual>
        <self_collide>0</self_collide>
        <enable_wind>0</enable_wind>
        <kinematic>0</kinematic>
      </link>
      <joint name='r_sho_roll' type='revolute'>
        <pose relative_to='r_sho_pitch_Link'>0.0234 0 0.03735 3.14159 1.57079 3.14159</pose>
        <parent>r_sho_pitch_Link</parent>
        <child>r_sho_roll_Link</child>
        <axis>
          <xyz>0 0 -1</xyz>
          <limit>
            <lower>-1.6</lower>
            <upper>-0.9</upper>
            <effort>4.1</effort>
            <velocity>4.71</velocity>
          </limit>
          <dynamics>
            <spring_reference>0</spring_reference>
            <spring_stiffness>0</spring_stiffness>
          </dynamics>
        </axis>
      </joint>
      <link name='r_sho_roll_Link'>
        <pose relative_to='r_sho_roll'>0 0 0 0 -0 0</pose>
        <inertial>
          <pose>-0.114571 0.000361 -0.0234 0 -0 0</pose>
          <mass>0.0683067</mass>
          <inertia>
            <ixx>1.14189e-05</ixx>
            <ixy>-1.22523e-09</ixy>
            <ixz>7.03693e-13</ixz>
            <iyy>2.35951e-05</iyy>
            <iyz>1.5685e-13</iyz>
            <izz>2.34186e-05</izz>
          </inertia>
        </inertial>
        <collision name='r_sho_roll_Link_collision'>
          <pose>0 0 0 0 -0 0</pose>
          <geometry>
            <mesh>
              <scale>1 1 1</scale>
              <uri>/home/mystique/dev_ws/install/diablo_bot/share/diablo_bot/description/meshes/r_sho_roll_Link.STL</uri>
            </mesh>
          </geometry>
          <max_contacts>10</max_contacts>
          <surface>
            <contact>
              <ode/>
            </contact>
            <bounce/>
            <friction>
              <torsional>
                <ode/>
              </torsional>
              <ode/>
            </friction>
          </surface>
        </collision>
        <visual name='r_sho_roll_Link_visual'>
          <pose>0 0 0 0 -0 0</pose>
          <geometry>
            <mesh>
              <scale>1 1 1</scale>
              <uri>/home/mystique/dev_ws/install/diablo_bot/share/diablo_bot/description/meshes/r_sho_roll_Link.STL</uri>
            </mesh>
          </geometry>
        </visual>
        <self_collide>0</self_collide>
        <enable_wind>0</enable_wind>
        <kinematic>0</kinematic>
      </link>
      <joint name='r_el' type='revolute'>
        <pose relative_to='r_sho_roll_Link'>-0.14975 0.0234 -0.0234 -1.5708 0 0</pose>
        <parent>r_sho_roll_Link</parent>
        <child>r_el_Link</child>
        <axis>
          <xyz>0 0 -1</xyz>
          <limit>
            <lower>-1.57</lower>
            <upper>0</upper>
            <effort>4.1</effort>
            <velocity>4.71</velocity>
          </limit>
          <dynamics>
            <spring_reference>0</spring_reference>
            <spring_stiffness>0</spring_stiffness>
          </dynamics>
        </axis>
      </joint>
      <link name='r_el_Link'>
        <pose relative_to='r_el'>0 0 0 0 -0 0</pose>
        <inertial>
          <pose>-0.068098 0.001511 -0.026841 0 -0 0</pose>
          <mass>0.305317</mass>
          <inertia>
            <ixx>0.0975727</ixx>
            <ixy>-4.21458e-05</ixy>
            <ixz>0.000414753</ixz>
            <iyy>1.0178</iyy>
            <iyz>0.00159474</iyz>
            <izz>0.931969</izz>
          </inertia>
        </inertial>
        <collision name='r_el_Link_collision'>
          <pose>0 0 0 0 -0 0</pose>
          <geometry>
            <mesh>
              <scale>1 1 1</scale>
              <uri>/home/mystique/dev_ws/install/diablo_bot/share/diablo_bot/description/meshes/r_el_Link.STL</uri>
            </mesh>
          </geometry>
          <max_contacts>10</max_contacts>
          <surface>
            <contact>
              <ode/>
            </contact>
            <bounce/>
            <friction>
              <torsional>
                <ode/>
              </torsional>
              <ode/>
            </friction>
          </surface>
        </collision>
        <collision name='r_el_Link_fixed_joint_lump__r_wrist_Link_collision_1'>
          <pose>-0.091 -0.000113 -0.023557 1.5708 0 -1.5708</pose>
          <geometry>
            <mesh>
              <scale>1 1 1</scale>
              <uri>/home/mystique/dev_ws/install/diablo_bot/share/diablo_bot/description/meshes/r_wrist_Link.STL</uri>
            </mesh>
          </geometry>
          <max_contacts>10</max_contacts>
          <surface>
            <contact>
              <ode/>
            </contact>
            <bounce/>
            <friction>
              <torsional>
                <ode/>
              </torsional>
              <ode/>
            </friction>
          </surface>
        </collision>
        <collision name='r_el_Link_fixed_joint_lump__r_index_base_Link_collision_2'>
          <pose>-0.18594 0.014369 -0.008534 -3.14159 -0 3.14159</pose>
          <geometry>
            <mesh>
              <scale>1 1 1</scale>
              <uri>/home/mystique/dev_ws/install/diablo_bot/share/diablo_bot/description/meshes/r_index_base_Link.STL</uri>
            </mesh>
          </geometry>
          <max_contacts>10</max_contacts>
          <surface>
            <contact>
              <ode/>
            </contact>
            <bounce/>
            <friction>
              <torsional>
                <ode/>
              </torsional>
              <ode/>
            </friction>
          </surface>
        </collision>
        <collision name='r_el_Link_fixed_joint_lump__r_index_middle_Link_collision_3'>
          <pose>-0.200475 0.021152 -0.007769 -3.14159 -0 3.14159</pose>
          <geometry>
            <mesh>
              <scale>1 1 1</scale>
              <uri>/home/mystique/dev_ws/install/diablo_bot/share/diablo_bot/description/meshes/r_index_middle_Link.STL</uri>
            </mesh>
          </geometry>
          <max_contacts>10</max_contacts>
          <surface>
            <contact>
              <ode/>
            </contact>
            <bounce/>
            <friction>
              <torsional>
                <ode/>
              </torsional>
              <ode/>
            </friction>
          </surface>
        </collision>
        <collision name='r_el_Link_fixed_joint_lump__r_index_tip_Link_collision_4'>
          <pose>-0.215391 0.026552 -0.005682 -3.14159 -0 3.14159</pose>
          <geometry>
            <mesh>
              <scale>1 1 1</scale>
              <uri>/home/mystique/dev_ws/install/diablo_bot/share/diablo_bot/description/meshes/r_index_tip_Link.STL</uri>
            </mesh>
          </geometry>
          <max_contacts>10</max_contacts>
          <surface>
            <contact>
              <ode/>
            </contact>
            <bounce/>
            <friction>
              <torsional>
                <ode/>
              </torsional>
              <ode/>
            </friction>
          </surface>
        </collision>
        <collision name='r_el_Link_fixed_joint_lump__r_mid_base_Link_collision_5'>
          <pose>-0.184747 0.013642 -0.048987 -3.14159 -0 3.14159</pose>
          <geometry>
            <mesh>
              <scale>1 1 1</scale>
              <uri>/home/mystique/dev_ws/install/diablo_bot/share/diablo_bot/description/meshes/r_mid_base_Link.STL</uri>
            </mesh>
          </geometry>
          <max_contacts>10</max_contacts>
          <surface>
            <contact>
              <ode/>
            </contact>
            <bounce/>
            <friction>
              <torsional>
                <ode/>
              </torsional>
              <ode/>
            </friction>
          </surface>
        </collision>
        <collision name='r_el_Link_fixed_joint_lump__r_mid_middle_Link_collision_6'>
          <pose>-0.198972 0.020236 -0.052455 -3.14159 -0 3.14159</pose>
          <geometry>
            <mesh>
              <scale>1 1 1</scale>
              <uri>/home/mystique/dev_ws/install/diablo_bot/share/diablo_bot/description/meshes/r_mid_middle_Link.STL</uri>
            </mesh>
          </geometry>
          <max_contacts>10</max_contacts>
          <surface>
            <contact>
              <ode/>
            </contact>
            <bounce/>
            <friction>
              <torsional>
                <ode/>
              </torsional>
              <ode/>
            </friction>
          </surface>
        </collision>
        <collision name='r_el_Link_fixed_joint_lump__r_mid_tip_Link_collision_7'>
          <pose>-0.213888 0.025636 -0.054543 -3.14159 -0 3.14159</pose>
          <geometry>
            <mesh>
              <scale>1 1 1</scale>
              <uri>/home/mystique/dev_ws/install/diablo_bot/share/diablo_bot/description/meshes/r_mid_tip_Link.STL</uri>
            </mesh>
          </geometry>
          <max_contacts>10</max_contacts>
          <surface>
            <contact>
              <ode/>
            </contact>
            <bounce/>
            <friction>
              <torsional>
                <ode/>
              </torsional>
              <ode/>
            </friction>
          </surface>
        </collision>
        <collision name='r_el_Link_fixed_joint_lump__r_thumb_base_Link_collision_8'>
          <pose>-0.169953 -0.026986 -0.028807 -3.14159 -0 3.14159</pose>
          <geometry>
            <mesh>
              <scale>1 1 1</scale>
              <uri>/home/mystique/dev_ws/install/diablo_bot/share/diablo_bot/description/meshes/r_thumb_base_Link.STL</uri>
            </mesh>
          </geometry>
          <max_contacts>10</max_contacts>
          <surface>
            <contact>
              <ode/>
            </contact>
            <bounce/>
            <friction>
              <torsional>
                <ode/>
              </torsional>
              <ode/>
            </friction>
          </surface>
        </collision>
        <collision name='r_el_Link_fixed_joint_lump__r_thumb_middle_Link_collision_9'>
          <pose>-0.175425 -0.042021 -0.030171 -3.14159 -0 3.14159</pose>
          <geometry>
            <mesh>
              <scale>1 1 1</scale>
              <uri>/home/mystique/dev_ws/install/diablo_bot/share/diablo_bot/description/meshes/r_thumb_middle_Link.STL</uri>
            </mesh>
          </geometry>
          <max_contacts>10</max_contacts>
          <surface>
            <contact>
              <ode/>
            </contact>
            <bounce/>
            <friction>
              <torsional>
                <ode/>
              </torsional>
              <ode/>
            </friction>
          </surface>
        </collision>
        <collision name='r_el_Link_fixed_joint_lump__r_thumb_tip_Link_collision_10'>
          <pose>-0.182187 -0.056522 -0.030171 -3.14159 -0 3.14159</pose>
          <geometry>
            <mesh>
              <scale>1 1 1</scale>
              <uri>/home/mystique/dev_ws/install/diablo_bot/share/diablo_bot/description/meshes/r_thumb_tip_Link.STL</uri>
            </mesh>
          </geometry>
          <max_contacts>10</max_contacts>
          <surface>
            <contact>
              <ode/>
            </contact>
            <bounce/>
            <friction>
              <torsional>
                <ode/>
              </torsional>
              <ode/>
            </friction>
          </surface>
        </collision>
        <visual name='r_el_Link_visual'>
          <pose>0 0 0 0 -0 0</pose>
          <geometry>
            <mesh>
              <scale>1 1 1</scale>
              <uri>/home/mystique/dev_ws/install/diablo_bot/share/diablo_bot/description/meshes/r_el_Link.STL</uri>
            </mesh>
          </geometry>
        </visual>
        <visual name='r_el_Link_fixed_joint_lump__r_wrist_Link_visual_1'>
          <pose>-0.091 -0.000113 -0.023557 1.5708 0 -1.5708</pose>
          <geometry>
            <mesh>
              <scale>1 1 1</scale>
              <uri>/home/mystique/dev_ws/install/diablo_bot/share/diablo_bot/description/meshes/r_wrist_Link.STL</uri>
            </mesh>
          </geometry>
        </visual>
        <visual name='r_el_Link_fixed_joint_lump__r_index_base_Link_visual_2'>
          <pose>-0.18594 0.014369 -0.008534 -3.14159 -0 3.14159</pose>
          <geometry>
            <mesh>
              <scale>1 1 1</scale>
              <uri>/home/mystique/dev_ws/install/diablo_bot/share/diablo_bot/description/meshes/r_index_base_Link.STL</uri>
            </mesh>
          </geometry>
        </visual>
        <visual name='r_el_Link_fixed_joint_lump__r_index_middle_Link_visual_3'>
          <pose>-0.200475 0.021152 -0.007769 -3.14159 -0 3.14159</pose>
          <geometry>
            <mesh>
              <scale>1 1 1</scale>
              <uri>/home/mystique/dev_ws/install/diablo_bot/share/diablo_bot/description/meshes/r_index_middle_Link.STL</uri>
            </mesh>
          </geometry>
        </visual>
        <visual name='r_el_Link_fixed_joint_lump__r_index_tip_Link_visual_4'>
          <pose>-0.215391 0.026552 -0.005682 -3.14159 -0 3.14159</pose>
          <geometry>
            <mesh>
              <scale>1 1 1</scale>
              <uri>/home/mystique/dev_ws/install/diablo_bot/share/diablo_bot/description/meshes/r_index_tip_Link.STL</uri>
            </mesh>
          </geometry>
        </visual>
        <visual name='r_el_Link_fixed_joint_lump__r_mid_base_Link_visual_5'>
          <pose>-0.184747 0.013642 -0.048987 -3.14159 -0 3.14159</pose>
          <geometry>
            <mesh>
              <scale>1 1 1</scale>
              <uri>/home/mystique/dev_ws/install/diablo_bot/share/diablo_bot/description/meshes/r_mid_base_Link.STL</uri>
            </mesh>
          </geometry>
        </visual>
        <visual name='r_el_Link_fixed_joint_lump__r_mid_middle_Link_visual_6'>
          <pose>-0.198972 0.020236 -0.052455 -3.14159 -0 3.14159</pose>
          <geometry>
            <mesh>
              <scale>1 1 1</scale>
              <uri>/home/mystique/dev_ws/install/diablo_bot/share/diablo_bot/description/meshes/r_mid_middle_Link.STL</uri>
            </mesh>
          </geometry>
        </visual>
        <visual name='r_el_Link_fixed_joint_lump__r_mid_tip_Link_visual_7'>
          <pose>-0.213888 0.025636 -0.054543 -3.14159 -0 3.14159</pose>
          <geometry>
            <mesh>
              <scale>1 1 1</scale>
              <uri>/home/mystique/dev_ws/install/diablo_bot/share/diablo_bot/description/meshes/r_mid_tip_Link.STL</uri>
            </mesh>
          </geometry>
        </visual>
        <visual name='r_el_Link_fixed_joint_lump__r_thumb_base_Link_visual_8'>
          <pose>-0.169953 -0.026986 -0.028807 -3.14159 -0 3.14159</pose>
          <geometry>
            <mesh>
              <scale>1 1 1</scale>
              <uri>/home/mystique/dev_ws/install/diablo_bot/share/diablo_bot/description/meshes/r_thumb_base_Link.STL</uri>
            </mesh>
          </geometry>
        </visual>
        <visual name='r_el_Link_fixed_joint_lump__r_thumb_middle_Link_visual_9'>
          <pose>-0.175425 -0.042021 -0.030171 -3.14159 -0 3.14159</pose>
          <geometry>
            <mesh>
              <scale>1 1 1</scale>
              <uri>/home/mystique/dev_ws/install/diablo_bot/share/diablo_bot/description/meshes/r_thumb_middle_Link.STL</uri>
            </mesh>
          </geometry>
        </visual>
        <visual name='r_el_Link_fixed_joint_lump__r_thumb_tip_Link_visual_10'>
          <pose>-0.182187 -0.056522 -0.030171 -3.14159 -0 3.14159</pose>
          <geometry>
            <mesh>
              <scale>1 1 1</scale>
              <uri>/home/mystique/dev_ws/install/diablo_bot/share/diablo_bot/description/meshes/r_thumb_tip_Link.STL</uri>
            </mesh>
          </geometry>
        </visual>
        <self_collide>0</self_collide>
        <enable_wind>0</enable_wind>
        <kinematic>0</kinematic>
      </link>
      <static>0</static>
      <plugin name='gazebo_ros2_control' filename='libgazebo_ros2_control.so'>
        <parameters>/home/mystique/dev_ws/install/diablo_bot/share/diablo_bot/config/diff_drive_controller.yaml</parameters>
      </plugin>
      <pose>0 0 0 0 -0 0</pose>
    </model>
    <state world_name='default'>
      <sim_time>90 435000000</sim_time>
      <real_time>118 21614216</real_time>
      <wall_time>1733290913 464728578</wall_time>
      <iterations>90435</iterations>
      <model name='ground_plane'>
        <pose>0 0 0 0 -0 0</pose>
        <scale>1 1 1</scale>
        <link name='link'>
          <pose>0 0 0 0 -0 0</pose>
          <velocity>0 0 0 0 -0 0</velocity>
          <acceleration>0 0 0 0 -0 0</acceleration>
          <wrench>0 0 0 0 -0 0</wrench>
        </link>
      </model>
      <model name='my_bot'>
        <pose>0.024417 -0.096841 0.23959 0 7.3e-05 0.151163</pose>
        <scale>1 1 1</scale>
        <link name='base_link'>
          <pose>0.024417 -0.096841 0.23959 0 7.3e-05 0.151163</pose>
          <velocity>0.001935 0.000351 0.000366 -0.001393 0.008075 0.000149</velocity>
          <acceleration>2.18677 0.418966 0.672483 2.90614 0.970413 -3.05581</acceleration>
          <wrench>18.833 3.60822 5.79157 0 -0 0</wrench>
        </link>
        <link name='l_el_Link'>
          <pose>-0.017203 0.096254 0.362696 -1.04345 1.04984 0.619076</pose>
          <velocity>-0.002723 0.009035 0.004453 0.032368 0.231268 0.057172</velocity>
          <acceleration>-0.482685 -0.226244 0.435287 0.124689 0.186704 -0.367706</acceleration>
          <wrench>-0.147372 -0.069076 0.132901 0 -0 0</wrench>
        </link>
        <link name='l_sho_pitch_Link'>
          <pose>-0.002483 -0.000139 0.501832 1.57085 -1.8e-05 -2.99028</pose>
          <velocity>0.00396 0.000704 0.000245 -0.006336 0.032473 0.00669</velocity>
          <acceleration>6.90686 1.28043 0.444806 2.28644 -0.513769 -2.68702</acceleration>
          <wrench>0.31421 0.05825 0.020235 0 -0 0</wrench>
        </link>
        <link name='l_sho_roll_Link'>
          <pose>0.015024 0.040309 0.501812 1.57015 -1.31756 -1.41871</pose>
          <velocity>0.00322 0.00058 -0.000192 0.06319 0.040324 0.00761</velocity>
          <acceleration>0.905061 0.244465 0.893589 -0.577836 -1.49101 -0.75296</acceleration>
          <wrench>0.061822 0.016699 0.061038 0 -0 0</wrench>
        </link>
        <link name='leg2_left_link_1'>
          <pose>-0.104599 0.073324 0.022983 3.14158 1.04381 -2.99044</pose>
          <velocity>0.000585 -0.000179 0.000938 0.006606 -0.0101 -0.003826</velocity>
          <acceleration>1.15273 0.330098 -6.07475 0.077413 1.37829 -0.979033</acceleration>
          <wrench>0.057637 0.016505 -0.303737 0 -0 0</wrench>
        </link>
        <link name='leg2_right_link_1'>
          <pose>-0.04115 -0.296438 0.015968 3.14159 -0.984023 -2.99042</pose>
          <velocity>0.001432 -7.4e-05 0.001391 0.004722 -0.025699 0.002816</velocity>
          <acceleration>0.17202 -0.179225 6.80056 -2.70961 1.3837 0.83921</acceleration>
          <wrench>0.008601 -0.008961 0.340028 0 -0 0</wrench>
        </link>
        <link name='motor_left_link_1'>
          <pose>0.0167 -0.043845 0.11859 0 0.819058 0.151163</pose>
          <velocity>0.000964 0.000178 0.000353 -0.001238 0.007177 0.000202</velocity>
          <acceleration>1.78259 0.33449 0.840573 1.8785 -1.0976 -0.141084</acceleration>
          <wrench>8.28906 1.55538 3.90866 0 -0 0</wrench>
        </link>
        <link name='motor_right_link_1'>
          <pose>0.032798 -0.149526 0.11859 -0 0.74803 0.151163</pose>
          <velocity>0.000986 0.000184 0.000389 -0.000663 0.002691 0.000306</velocity>
          <acceleration>1.79134 0.338418 1.01195 2.09612 -0.243738 -2.84008</acceleration>
          <wrench>8.32973 1.57364 4.70557 0 -0 0</wrench>
        </link>
        <link name='r_el_Link'>
          <pose>0.055165 -0.267063 0.355534 -1.37324 -1.13098 3.10358</pose>
          <velocity>0.061286 0.022047 0.004254 0.02883 0.426477 -0.062596</velocity>
          <acceleration>-1.23953 -0.13132 -0.014905 -2.47502 0.184129 -0.535146</acceleration>
          <wrench>-0.37845 -0.040094 -0.004551 0 -0 0</wrench>
        </link>
        <link name='r_sho_pitch_Link'>
          <pose>0.027521 -0.197167 0.501832 1.57069 -0.114451 0.151243</pose>
          <velocity>0.004003 0.000707 0.000444 0.060789 -0.402244 0.000888</velocity>
          <acceleration>7.26587 1.33402 1.00799 -2.30098 -1.04743 0.588761</acceleration>
          <wrench>0.330543 0.060688 0.045856 0 -0 0</wrench>
        </link>
        <link name='r_sho_roll_Link'>
          <pose>0.056134 -0.230585 0.504496 0.632338 -1.4289 2.6555</pose>
          <velocity>0.002976 0.000648 0.009884 0.143788 -0.389216 0.008784</velocity>
          <acceleration>0.714466 0.23663 0.202152 -2.24249 1.18577 -1.18627</acceleration>
          <wrench>0.048803 0.016163 0.013808 0 -0 0</wrench>
        </link>
        <link name='wheel_left_link_1'>
          <pose>-0.228395 0.082486 0.093394 9e-06 3.8e-05 0.151163</pose>
          <velocity>-0.000233 -0.00012 -0.00031 0.001531 0.00283 -0.003445</velocity>
          <acceleration>-0.456321 0.352143 -8.79039 2.77492 -0.771893 -0.853469</acceleration>
          <wrench>-1.1408 0.880356 -21.976 0 -0 0</wrench>
        </link>
        <link name='wheel_right_link_1'>
          <pose>0.078275 -0.306265 0.093481 5e-06 -0.9244 0.151163</pose>
          <velocity>-0.0006 4.1e-05 0.004119 -0.000578 -0.005821 0.002183</velocity>
          <acceleration>-1.13864 0.125006 8.33465 3.11882 -0.652914 -1.92382</acceleration>
          <wrench>-2.84659 0.312515 20.8366 0 -0 0</wrench>
        </link>
      </model>
      <light name='sun'>
        <pose>0 0 10 0 -0 0</pose>
      </light>
    </state>
    <gui fullscreen='0'>
      <camera name='user_camera'>
        <pose>4.23856 -5.85867 1.75693 0 0.275643 2.35619</pose>
        <view_controller>orbit</view_controller>
        <projection_type>perspective</projection_type>
      </camera>
    </gui>
  </world>
</sdf>
